Workbook

Sheet Carta Gantt
A1: Carta Gantt - Proyecto "Aprueba Administracion" - Modulo de pasarela de pago y suscripcion
A2: Duoc UC | PTY4614 - Capstone | Empresa colaboradora: Alloxentric | Docente: Luis Bravo | Equipo: Sebastian Araya Hernandez, Cesar Garrido Trujillo, Thiare Gomez | AH2: Fecha de corte | AI2: Fecha de revisión
A3: Fecha inicio Semana 1: | B3: 46247 | D3: Semana actual del proyecto: | F3: =MAX(1,MIN(18,ROUNDUP(($AH$3-$B$3+1)/7,0))) -> 12 | H3: Corte del avance: 30-10-2026. Inicio: 13-08-2026. La semana del proyecto se calcula desde ese inicio. Las fechas académicas se rigen por la pauta de la asignatura. | AH3: 46325 | AI3: 46325
A4: ACTIVIDAD | D4: FASES DEL PROYECTO | G4: DATOS DE PLANIFICACION | O4: FASE 1 (S1-S4) | S4: FASE 2 (S5-S16) | AE4: FASE 3 (S17-S18)
A5: ID | B5: Incremento | C5: Actividad | D5: Fase 1 | E5: Fase 2 | F5: Fase 3 | G5: Responsable | H5: Tipo | I5: Sem. Inicio | J5: Sem. Fin | K5: Duracion (semanas) | L5: Fecha Inicio | M5: Fecha Fin | N5: Estado | O5: S1 | P5: S2 | Q5: S3 | R5: S4 | S5: S5 | T5: S6 | U5: S7 | V5: S8 | W5: S9 | X5: S10 | Y5: S11 | Z5: S12 | AA5: S13 | AB5: S14 | AC5: S15 | AD5: S16 | AE5: S17 | AF5: S18 | AG5: Observaciones del avance
A6: 1 | B6: Incremento 1: Levantamiento y Diseño (S1-S4) | C6: Primera reunión con la empresa colaboradora (Alloxentric) - kickoff | D6: X | G6: Todo el equipo | H6: Tarea | I6: 3 | J6: 3 | K6: =J6-I6+1 -> 1 | L6: =$B$3+(I6-1)*7 -> 46261 | M6: =$B$3+(J6)*7-1 -> 46267 | N6: Completado
A7: 2 | B7: Incremento 1: Levantamiento y Diseño (S1-S4) | C7: Levantamiento de requerimientos funcionales y no funcionales, historias de usuario, diagrama de actividad | D7: X | G7: Sebastián Araya | H7: Tarea | I7: 1 | J7: 2 | K7: =J7-I7+1 -> 2 | L7: =$B$3+(I7-1)*7 -> 46247 | M7: =$B$3+(J7)*7-1 -> 46260 | N7: Completado
A8: 3 | B8: Incremento 1: Levantamiento y Diseño (S1-S4) | C8: Análisis de la plataforma "Aprueba Administracion" existente | D8: X | G8: Todo el equipo | H8: Tarea | I8: 1 | J8: 2 | K8: =J8-I8+1 -> 2 | L8: =$B$3+(I8-1)*7 -> 46247 | M8: =$B$3+(J8)*7-1 -> 46260 | N8: Completado
A9: 4 | B9: Incremento 1: Levantamiento y Diseño (S1-S4) | C9: Definición de alcance, objetivos, mockups, planificación (EDT y Carta Gantt), actas de reuniones, estados de avance y resolución de conflictos | D9: X | G9: Thiare Gomez | H9: Tarea | I9: 2 | J9: 3 | K9: =J9-I9+1 -> 2 | L9: =$B$3+(I9-1)*7 -> 46254 | M9: =$B$3+(J9)*7-1 -> 46267 | N9: Completado
A10: 5 | B10: Incremento 1: Levantamiento y Diseño (S1-S4) | C10: Diseño del modelo de datos y de clases: planes, suscripciones y usuarios + Documentación stakeholder's | D10: X | G10: Cesar Garrido | H10: Tarea | I10: 2 | J10: 3 | K10: =J10-I10+1 -> 2 | L10: =$B$3+(I10-1)*7 -> 46254 | M10: =$B$3+(J10)*7-1 -> 46267 | N10: Completado
A11: 6 | B11: Incremento 1: Levantamiento y Diseño (S1-S4) | C11: Elaboración de Documentación Formal / Plan de Proyecto | D11: X | G11: Thiare Gomez | H11: Tarea | I11: 3 | J11: 3 | K11: =J11-I11+1 -> 1 | L11: =$B$3+(I11-1)*7 -> 46261 | M11: =$B$3+(J11)*7-1 -> 46267 | N11: Completado
A12: 7 | B12: Incremento 1: Levantamiento y Diseño (S1-S4) | C12: Hito: entrega Documentacion Formal / Plan de Proyecto | D12: X | G12: Todo el equipo | H12: Hito | I12: 3 | J12: 3 | K12: =J12-I12+1 -> 1 | L12: =$B$3+(I12-1)*7 -> 46261 | M12: =$B$3+(J12)*7-1 -> 46267 | N12: Completado | Q12: ◆
A13: 8 | B13: Incremento 1: Levantamiento y Diseño (S1-S4) | C13: Elaboración Informe Fase 1 | D13: X | G13: Todo el equipo | H13: Tarea | I13: 3 | J13: 4 | K13: =J13-I13+1 -> 2 | L13: =$B$3+(I13-1)*7 -> 46261 | M13: =$B$3+(J13)*7-1 -> 46274 | N13: Completado
A14: 9 | B14: Incremento 1: Levantamiento y Diseño (S1-S4) | C14: Preparación y presentación inicial del proyecto | D14: X | G14: Todo el equipo | H14: Tarea | I14: 4 | J14: 4 | K14: =J14-I14+1 -> 1 | L14: =$B$3+(I14-1)*7 -> 46268 | M14: =$B$3+(J14)*7-1 -> 46274 | N14: Completado
A15: 10 | B15: Incremento 1: Levantamiento y Diseño (S1-S4) | C15: Hito: presentacion inicial | D15: X | G15: Todo el equipo | H15: Hito | I15: 4 | J15: 4 | K15: =J15-I15+1 -> 1 | L15: =$B$3+(I15-1)*7 -> 46268 | M15: =$B$3+(J15)*7-1 -> 46274 | N15: Completado | R15: ◆
A16: 11 | B16: Incremento 2: Gestión de Planes y Suscripciones (S4-S6) | C16: Diseño de la arquitectura (módulo pago y suscripción) | E16: X | G16: Todo el equipo | H16: Tarea | I16: 4 | J16: 5 | K16: =J16-I16+1 -> 2 | L16: =$B$3+(I16-1)*7 -> 46268 | M16: =$B$3+(J16)*7-1 -> 46281 | N16: En curso | AG16: Diseño técnico y modelo de datos disponibles; no acredita validación integral de la arquitectura.
A17: 12 | B17: Incremento 2: Gestión de Planes y Suscripciones (S4-S6) | C17: Desarrollo CRUD de planes de suscripción (backend) | E17: X | G17: Sebastian Araya | H17: Tarea | I17: 4 | J17: 5 | K17: =J17-I17+1 -> 2 | L17: =$B$3+(I17-1)*7 -> 46268 | M17: =$B$3+(J17)*7-1 -> 46281 | N17: En curso | AG17: IF-08: crear, eliminar, publicar y cambiar precio pendientes de habilitación; no se acredita CRUD completo. Fuente: ../Resultados de las pruebas/Resultados_de_pruebas.docx.
A18: 13 | B18: Incremento 2: Gestión de Planes y Suscripciones (S4-S6) | C18: Desarrollo de interfaz de gestión de planes (frontend) | E18: X | G18: Cesar Garrido | H18: Tarea | I18: 5 | J18: 6 | K18: =J18-I18+1 -> 2 | L18: =$B$3+(I18-1)*7 -> 46275 | M18: =$B$3+(J18)*7-1 -> 46288 | N18: En curso | AG18: Consulta visible en IF-08; edición no ejecutada ni persistencia comprobada. Fuente: ../Resultados de las pruebas/Resultados_de_pruebas.docx.
A19: 14 | B19: Incremento 2: Gestión de Planes y Suscripciones (S4-S6) | C19: Implementación de asignación de suscripción a usuario | E19: X | G19: Sebastian Araya | H19: Tarea | I19: 5 | J19: 6 | K19: =J19-I19+1 -> 2 | L19: =$B$3+(I19-1)*7 -> 46275 | M19: =$B$3+(J19)*7-1 -> 46288 | N19: En curso | AG19: Datos y permisos recibidos. Persistencia observada; acceso completo por M2 e Historia sin validar.
A20: 15 | B20: Incremento 2: Gestión de Planes y Suscripciones (S4-S6) | C20: Pruebas unitarias del módulo de planes | E20: X | G20: Thiare Gomez | H20: Tarea | I20: 6 | J20: 6 | K20: =J20-I20+1 -> 1 | L20: =$B$3+(I20-1)*7 -> 46282 | M20: =$B$3+(J20)*7-1 -> 46288 | N20: Planificado | AG20: No se recibieron resultados de pruebas unitarias. IF-08 es prueba de interfaz, no unitaria. Fuente: ../Resultados de las pruebas/Resultados_de_pruebas.docx.
A21: 16 | B21: Incremento 2: Gestión de Planes y Suscripciones (S4-S6) | C21: Hito: Incremento 2 validado | E21: X | G21: Todo el equipo | H21: Hito | I21: 6 | J21: 6 | K21: =J21-I21+1 -> 1 | L21: =$B$3+(I21-1)*7 -> 46282 | M21: =$B$3+(J21)*7-1 -> 46288 | N21: En curso | T21: ◆ | AG21: I2 no validado integralmente: CRUD y cambios de precio pendientes. Fuente: ../Resultados de las pruebas/Resultados_de_pruebas.docx.
A22: 17 | B22: Incremento 3: Checkout y Suscripción (S7-S9) | C22: Diseño UX/UI del flujo de checkout | E22: X | G22: Thiare Gomez | H22: Tarea | I22: 7 | J22: 7 | K22: =J22-I22+1 -> 1 | L22: =$B$3+(I22-1)*7 -> 46289 | M22: =$B$3+(J22)*7-1 -> 46295 | N22: Completado
A23: 18 | B23: Incremento 3: Checkout y Suscripción (S7-S9) | C23: Desarrollo del flujo de checkout (plan y datos de pago) | E23: X | G23: Cesar Garrido | H23: Tarea | I23: 7 | J23: 8 | K23: =J23-I23+1 -> 2 | L23: =$B$3+(I23-1)*7 -> 46289 | M23: =$B$3+(J23)*7-1 -> 46302 | N23: Completado | AG23: Estado al 21-10-2026; evidencia DAD_20_TICKETS_CORESTREAM_12-10-2026.docx (T2, T11); cubre apertura de Checkout y retorno a Mi plan para la compra mensual; pendiente: validación end-to-end ampliada (ver fila 27).
A24: 19 | B24: Incremento 3: Checkout y Suscripción (S7-S9) | C24: Validación de formularios y reglas de negocio | E24: X | G24: Sebastian Araya | H24: Tarea | I24: 7 | J24: 8 | K24: =J24-I24+1 -> 2 | L24: =$B$3+(I24-1)*7 -> 46289 | M24: =$B$3+(J24)*7-1 -> 46302 | N24: En curso | AG24: IF-01 valida login; IF-13 registra hallazgos de contratación. No prueba todas las reglas de negocio. Fuente: ../Resultados de las pruebas/Resultados_de_pruebas.docx.
A25: 20 | B25: Incremento 3: Checkout y Suscripción (S7-S9) | C25: Integración de checkout con módulo de suscripciones | E25: X | G25: Sebastian Araya | H25: Tarea | I25: 8 | J25: 9 | K25: =J25-I25+1 -> 2 | L25: =$B$3+(I25-1)*7 -> 46296 | M25: =$B$3+(J25)*7-1 -> 46309 | N25: Completado | AG25: Compra aprobada vinculada a suscripción y factura. Contratación anual documentada; cobertura de materias parcial.
A26: 21 | B26: Incremento 3: Checkout y Suscripción (S7-S9) | C26: Mockups y prototipo navegable de checkout | E26: X | G26: Thiare Gomez | H26: Tarea | I26: 8 | J26: 9 | K26: =J26-I26+1 -> 2 | L26: =$B$3+(I26-1)*7 -> 46296 | M26: =$B$3+(J26)*7-1 -> 46309 | N26: Completado
A27: 22 | B27: Incremento 3: Checkout y Suscripción (S7-S9) | C27: Pruebas end-to-end del flujo de checkout | E27: X | G27: Todo el equipo | H27: Tarea | I27: 9 | J27: 9 | K27: =J27-I27+1 -> 1 | L27: =$B$3+(I27-1)*7 -> 46303 | M27: =$B$3+(J27)*7-1 -> 46309 | N27: En curso | AG27: Compra mensual y anual evaluadas. Ciclo de suscripción y cobertura de materias parciales.
A28: 23 | B28: Incremento 3: Checkout y Suscripción (S7-S9) | C28: Hito: Incremento 3 validado | E28: X | G28: Todo el equipo | H28: Hito | I28: 9 | J28: 9 | K28: =J28-I28+1 -> 1 | L28: =$B$3+(I28-1)*7 -> 46303 | M28: =$B$3+(J28)*7-1 -> 46309 | N28: En curso | W28: ◆ | AG28: I3 parcial. PG-08/09 aprobados en interfaz; cobertura completa de contratación pendiente. Fuente: ../Resultados de las pruebas/Resultados_de_pruebas.docx.
A29: 24 | B29: Incremento 4: Integración Pasarela de Pago - Stripe (S10-S13) | C29: Configuración de cuenta sandbox Stripe | E29: X | G29: Sebastian Araya | H29: Tarea | I29: 10 | J29: 10 | K29: =J29-I29+1 -> 1 | L29: =$B$3+(I29-1)*7 -> 46310 | M29: =$B$3+(J29)*7-1 -> 46316 | N29: Completado | AG29: Sandbox operativo. Pagos: 25 casos, 11 aprobados, 13 parciales y 1 no ejecutado.
A30: 25 | B30: Incremento 4: Integración Pasarela de Pago - Stripe (S10-S13) | C30: Integración API Stripe (checkout session y webhooks) | E30: X | G30: Sebastian Araya | H30: Tarea | I30: 10 | J30: 11 | K30: =J30-I30+1 -> 2 | L30: =$B$3+(I30-1)*7 -> 46310 | M30: =$B$3+(J30)*7-1 -> 46323 | N30: En curso | AG30: Checkout y eventos disponibles. Reentrega real acreditada; concurrencia y desorden con límites de entorno.
A31: 26 | B31: Incremento 4: Integración Pasarela de Pago - Stripe (S10-S13) | C31: Manejo de estados de pago (pendiente, aprobado, rechazado) | E31: X | G31: Cesar Garrido | H31: Tarea | I31: 11 | J31: 12 | K31: =J31-I31+1 -> 2 | L31: =$B$3+(I31-1)*7 -> 46317 | M31: =$B$3+(J31)*7-1 -> 46330 | N31: En curso | AG31: Pagos aprobados, fallidos y recuperados documentados. Ciclo temporal y auditoría incompletos.
A32: 27 | B32: Incremento 4: Integración Pasarela de Pago - Stripe (S10-S13) | C32: Confirmación de pago y activación automática de suscripción | E32: X | G32: Sebastian Araya | H32: Tarea | I32: 12 | J32: 12 | K32: =J32-I32+1 -> 1 | L32: =$B$3+(I32-1)*7 -> 46324 | M32: =$B$3+(J32)*7-1 -> 46330 | N32: En curso | AG32: Activación documentada en los recorridos probados. Validación por todas las materias pendiente.
A33: 28 | B33: Incremento 4: Integración Pasarela de Pago - Stripe (S10-S13) | C33: Notificaciones al usuario (correo y confirmación en pantalla) | E33: X | G33: Cesar Garrido | H33: Tarea | I33: 12 | J33: 13 | K33: =J33-I33+1 -> 2 | L33: =$B$3+(I33-1)*7 -> 46324 | M33: =$B$3+(J33)*7-1 -> 46337 | N33: Planificado | AG33: PG21 no ejecutado: canal y emisor financiero sin acreditar.
A34: 29 | B34: Incremento 4: Integración Pasarela de Pago - Stripe (S10-S13) | C34: Pruebas de integración con pasarela (casos exito y error) | E34: X | G34: Todo el equipo | H34: Tarea | I34: 13 | J34: 13 | K34: =J34-I34+1 -> 1 | L34: =$B$3+(I34-1)*7 -> 46331 | M34: =$B$3+(J34)*7-1 -> 46337 | N34: En curso | AG34: Evaluación del avance realizada: 57 casos, 30 aprobados, 17 parciales, 2 fallidos, 7 bloqueados y 1 no ejecutado.
A35: 30 | B35: Incremento 4: Integración Pasarela de Pago - Stripe (S10-S13) | C35: Hito: Incremento 4 validado | E35: X | G35: Todo el equipo | H35: Hito | I35: 13 | J35: 13 | K35: =J35-I35+1 -> 1 | L35: =$B$3+(I35-1)*7 -> 46331 | M35: =$B$3+(J35)*7-1 -> 46337 | N35: Planificado | AA35: ◆ | AG35: Integración parcial; faltan criterios de ciclo, auditoría y rendimiento para validar el incremento completo.
A36: 31 | B36: Incremento 5: Cierre, Pruebas Integrales y Entrega (S14-S16) | C36: Pruebas integrales del sistema (regresión) | E36: X | G36: Todo el equipo | H36: Tarea | I36: 14 | J36: 14 | K36: =J36-I36+1 -> 1 | L36: =$B$3+(I36-1)*7 -> 46338 | M36: =$B$3+(J36)*7-1 -> 46344 | N36: Planificado
A37: 32 | B37: Incremento 5: Cierre, Pruebas Integrales y Entrega (S14-S16) | C37: Corrección de observaciones y ajustes finales | E37: X | G37: Todo el equipo | H37: Tarea | I37: 14 | J37: 15 | K37: =J37-I37+1 -> 2 | L37: =$B$3+(I37-1)*7 -> 46338 | M37: =$B$3+(J37)*7-1 -> 46351 | N37: Planificado
A38: 33 | B38: Incremento 5: Cierre, Pruebas Integrales y Entrega (S14-S16) | C38: Elaboración de manual de usuario y documentación técnica | E38: X | G38: Thiare Gomez | H38: Tarea | I38: 15 | J38: 15 | K38: =J38-I38+1 -> 1 | L38: =$B$3+(I38-1)*7 -> 46345 | M38: =$B$3+(J38)*7-1 -> 46351 | N38: Planificado
A39: 34 | B39: Incremento 5: Cierre, Pruebas Integrales y Entrega (S14-S16) | C39: Preparación de evidencias y respaldo del proyecto | E39: X | G39: Cesar Garrido | H39: Tarea | I39: 15 | J39: 16 | K39: =J39-I39+1 -> 2 | L39: =$B$3+(I39-1)*7 -> 46345 | M39: =$B$3+(J39)*7-1 -> 46358 | N39: Planificado
A40: 35 | B40: Incremento 5: Cierre, Pruebas Integrales y Entrega (S14-S16) | C40: Validación final con empresa colaboradora (Alloxentric) | E40: X | G40: Todo el equipo | H40: Tarea | I40: 16 | J40: 16 | K40: =J40-I40+1 -> 1 | L40: =$B$3+(I40-1)*7 -> 46352 | M40: =$B$3+(J40)*7-1 -> 46358 | N40: Planificado
...

Sheet Resumen Ejecutivo
A1: Resumen Ejecutivo del Cronograma
A2: Duracion total planificada: 18 semanas | Metodologia: incremental (5 incrementos) + cierre institucional
A4: Semana actual | C4: Duracion total (semanas) | E4: Hitos totales | G4: Porcentaje de tareas completadas
A5: ='Carta Gantt'!F3 -> 12 | C5: 18 | E5: =COUNTIF('Carta Gantt'!$H$6:$H$49,"Hito") -> 8 | G5: =COUNTIFS('Carta Gantt'!$H$6:$H$49,"Tarea",'Carta Gantt'!$N$6:$N$49,"Completado")/COUNTIF('Carta Gantt'!$H$6:$H$49,"Tarea") -> 0.36111111
A8: Fase / Incremento | B8: Sem. Inicio | C8: Sem. Fin | D8: Duracion (sem) | E8: N° Tareas | F8: N° Hitos | G8: Tareas completadas
A9: Incremento 1: Levantamiento y Diseño (S1-S4) | B9: =_xlfn.MINIFS('Carta Gantt'!$I$6:$I$49,'Carta Gantt'!$B$6:$B$49,$A9) -> 1 | C9: =_xlfn.MINIFS('Carta Gantt'!$I$6:$I$49,'Carta Gantt'!$B$6:$B$49,$A9) -> 1 | D9: =_xlfn.MINIFS('Carta Gantt'!$I$6:$I$49,'Carta Gantt'!$B$6:$B$49,$A9) -> 1 | E9: =_xlfn.MINIFS('Carta Gantt'!$I$6:$I$49,'Carta Gantt'!$B$6:$B$49,$A9) -> 1 | F9: =_xlfn.MINIFS('Carta Gantt'!$I$6:$I$49,'Carta Gantt'!$B$6:$B$49,$A9) -> 1 | G9: =_xlfn.MINIFS('Carta Gantt'!$I$6:$I$49,'Carta Gantt'!$B$6:$B$49,$A9) -> 1
A10: Incremento 2: Gestión de Planes y Suscripciones (S4-S6) | B10: =_xlfn.MINIFS('Carta Gantt'!$I$6:$I$49,'Carta Gantt'!$B$6:$B$49,$A10) -> 4 | C10: =_xlfn.MINIFS('Carta Gantt'!$I$6:$I$49,'Carta Gantt'!$B$6:$B$49,$A10) -> 4 | D10: =_xlfn.MINIFS('Carta Gantt'!$I$6:$I$49,'Carta Gantt'!$B$6:$B$49,$A10) -> 4 | E10: =_xlfn.MINIFS('Carta Gantt'!$I$6:$I$49,'Carta Gantt'!$B$6:$B$49,$A10) -> 4 | F10: =_xlfn.MINIFS('Carta Gantt'!$I$6:$I$49,'Carta Gantt'!$B$6:$B$49,$A10) -> 4 | G10: =_xlfn.MINIFS('Carta Gantt'!$I$6:$I$49,'Carta Gantt'!$B$6:$B$49,$A10) -> 4
A11: Incremento 3: Checkout y Suscripción (S7-S9) | B11: =_xlfn.MINIFS('Carta Gantt'!$I$6:$I$49,'Carta Gantt'!$B$6:$B$49,$A11) -> 7 | C11: =_xlfn.MINIFS('Carta Gantt'!$I$6:$I$49,'Carta Gantt'!$B$6:$B$49,$A11) -> 7 | D11: =_xlfn.MINIFS('Carta Gantt'!$I$6:$I$49,'Carta Gantt'!$B$6:$B$49,$A11) -> 7 | E11: =_xlfn.MINIFS('Carta Gantt'!$I$6:$I$49,'Carta Gantt'!$B$6:$B$49,$A11) -> 7 | F11: =_xlfn.MINIFS('Carta Gantt'!$I$6:$I$49,'Carta Gantt'!$B$6:$B$49,$A11) -> 7 | G11: =_xlfn.MINIFS('Carta Gantt'!$I$6:$I$49,'Carta Gantt'!$B$6:$B$49,$A11) -> 7
A12: Incremento 4: Integración Pasarela de Pago - Stripe (S10-S13) | B12: =_xlfn.MINIFS('Carta Gantt'!$I$6:$I$49,'Carta Gantt'!$B$6:$B$49,$A12) -> 10 | C12: =_xlfn.MINIFS('Carta Gantt'!$I$6:$I$49,'Carta Gantt'!$B$6:$B$49,$A12) -> 10 | D12: =_xlfn.MINIFS('Carta Gantt'!$I$6:$I$49,'Carta Gantt'!$B$6:$B$49,$A12) -> 10 | E12: =_xlfn.MINIFS('Carta Gantt'!$I$6:$I$49,'Carta Gantt'!$B$6:$B$49,$A12) -> 10 | F12: =_xlfn.MINIFS('Carta Gantt'!$I$6:$I$49,'Carta Gantt'!$B$6:$B$49,$A12) -> 10 | G12: =_xlfn.MINIFS('Carta Gantt'!$I$6:$I$49,'Carta Gantt'!$B$6:$B$49,$A12) -> 10
A13: Incremento 5: Cierre, Pruebas Integrales y Entrega (S14-S16) | B13: =_xlfn.MINIFS('Carta Gantt'!$I$6:$I$49,'Carta Gantt'!$B$6:$B$49,$A13) -> 14 | C13: =_xlfn.MINIFS('Carta Gantt'!$I$6:$I$49,'Carta Gantt'!$B$6:$B$49,$A13) -> 14 | D13: =_xlfn.MINIFS('Carta Gantt'!$I$6:$I$49,'Carta Gantt'!$B$6:$B$49,$A13) -> 14 | E13: =_xlfn.MINIFS('Carta Gantt'!$I$6:$I$49,'Carta Gantt'!$B$6:$B$49,$A13) -> 14 | F13: =_xlfn.MINIFS('Carta Gantt'!$I$6:$I$49,'Carta Gantt'!$B$6:$B$49,$A13) -> 14 | G13: =_xlfn.MINIFS('Carta Gantt'!$I$6:$I$49,'Carta Gantt'!$B$6:$B$49,$A13) -> 14
A14: Fase 3: Cierre Proyecto (S17-S18) | B14: =_xlfn.MINIFS('Carta Gantt'!$I$6:$I$49,'Carta Gantt'!$B$6:$B$49,$A14) -> 17 | C14: =_xlfn.MINIFS('Carta Gantt'!$I$6:$I$49,'Carta Gantt'!$B$6:$B$49,$A14) -> 17 | D14: =_xlfn.MINIFS('Carta Gantt'!$I$6:$I$49,'Carta Gantt'!$B$6:$B$49,$A14) -> 17 | E14: =_xlfn.MINIFS('Carta Gantt'!$I$6:$I$49,'Carta Gantt'!$B$6:$B$49,$A14) -> 17 | F14: =_xlfn.MINIFS('Carta Gantt'!$I$6:$I$49,'Carta Gantt'!$B$6:$B$49,$A14) -> 17 | G14: =_xlfn.MINIFS('Carta Gantt'!$I$6:$I$49,'Carta Gantt'!$B$6:$B$49,$A14) -> 17
A15: Gestión Transversal (S1-S18) | B15: =_xlfn.MINIFS('Carta Gantt'!$I$6:$I$49,'Carta Gantt'!$B$6:$B$49,$A15) -> 1 | C15: =_xlfn.MINIFS('Carta Gantt'!$I$6:$I$49,'Carta Gantt'!$B$6:$B$49,$A15) -> 1 | D15: =_xlfn.MINIFS('Carta Gantt'!$I$6:$I$49,'Carta Gantt'!$B$6:$B$49,$A15) -> 1 | E15: =_xlfn.MINIFS('Carta Gantt'!$I$6:$I$49,'Carta Gantt'!$B$6:$B$49,$A15) -> 1 | F15: =_xlfn.MINIFS('Carta Gantt'!$I$6:$I$49,'Carta Gantt'!$B$6:$B$49,$A15) -> 1 | G15: =_xlfn.MINIFS('Carta Gantt'!$I$6:$I$49,'Carta Gantt'!$B$6:$B$49,$A15) -> 1
A17: Nota: el porcentaje da el mismo peso a cada tarea; no representa esfuerzo invertido ni cumplimiento funcional. Los estados «En curso» no suman al porcentaje.

Sheet Hitos
A1: Hitos y Entregables del Proyecto
A3: ID | B3: Hito / Entregable | C3: Fase | D3: Semana | E3: Fecha estimada
B4: Selección y definición del proyecto APT (Aprueba Administración) | C4: Incremento 1: Levantamiento y Diseño (S1-S4) | D4: S2 | E4: 46255
B5: Entrega de contenido completo del proyecto por parte de la empresa | C5: Incremento 1: Levantamiento y Diseño (S1-S4) | D5: S3 | E5: 46262
B6: Asignación del módulo: pasarela de pago y suscripción | C6: Incremento 1: Levantamiento y Diseño (S1-S4) | D6: S3 | E6: 46265
A7: 7 | B7: Hito: entrega Documentación Formal / Plan de Proyecto | C7: Incremento 1: Levantamiento y Diseño (S1-S4) | D7: S3 | E7: ='Carta Gantt'!M12 -> 46267
A8: 10 | B8: Hito: presentación inicial | C8: Incremento 1: Levantamiento y Diseño (S1-S4) | D8: S4 | E8: ='Carta Gantt'!M15 -> 46274
A9: 16 | B9: Hito: Incremento 2 validado | C9: Incremento 2: Gestión de Planes y Suscripciones (S4-S6) | D9: S6 | E9: ='Carta Gantt'!M21 -> 46288
A10: 23 | B10: Hito: Incremento 3 validado | C10: Incremento 3: Checkout y Suscripción (S7-S9) | D10: S9 | E10: ='Carta Gantt'!M28 -> 46309
A11: 30 | B11: Hito: Incremento 4 validado | C11: Incremento 4: Integración Pasarela de Pago - Stripe (S10-S13) | D11: S13 | E11: ='Carta Gantt'!M35 -> 46337
A12: 36 | B12: Hito: Incremento 5 validado | C12: Incremento 5: Cierre, Pruebas Integrales y Entrega (S14-S16) | D12: S16 | E12: ='Carta Gantt'!M41 -> 46358
A13: 40 | B13: Hito: entrega Informe Final | C13: Fase 3: Cierre Proyecto (S17-S18) | D13: S18 | E13: ='Carta Gantt'!M45 -> 46372
A14: 41 | B14: Hito: presentacion Final | C14: Fase 3: Cierre Proyecto (S17-S18) | D14: S18 | E14: ='Carta Gantt'!M46 -> 46372

Sheet Descripcion Actividades
A1: Descripcion de Actividades
A2: Describe en detalle cada actividad presentada en la Carta Gantt, indicando a que Fase(s) del proyecto pertenece.
A4: ID | B4: Actividad | C4: Fase 1 | D4: Fase 2 | E4: Fase 3 | F4: Descripcion
A5: 1 | B5: Primera reunión con la empresa colaboradora (Alloxentric) - kickoff | C5: X | F5: Reunión inicial con la empresa colaboradora Alloxentric y el docente guía para presentar al equipo, validar expectativas y acordar la modalidad de trabajo del capstone.
A6: 2 | B6: Levantamiento de requerimientos funcionales y no funcionales, historias de usuario, diagrama de actividad | C6: X | F6: Recopilación y documentación de los requerimientos funcionales (que debe hacer el sistema) y no funcionales (seguridad, usabilidad, rendimiento) del modulo de pasarela de pago y suscripcion, además d elas historias de usuario y diagramas de actividad
A7: 3 | B7: Análisis de la plataforma "Aprueba Administracion" existente | C7: X | F7: Revision de la plataforma "Aprueba Administracion" ya existente para identificar sus modulos actuales, tecnologias utilizadas y puntos de integracion con el nuevo modulo.
A8: 4 | B8: Definicion de alcance, objetivos, mockups inicial, planificación (EDT y Carta Gantt), actas de reuniones, estados de avance y resolución de conflictos | C8: X | F8: Toda la documentación formal, definición formal del alcance del proyecto, los objetivos general y especificos, y elaboración de la Estructura de Desglose de Trabajo (EDT), la Carta Gantt, actas de reuniones, estados de avance y resolución de conflictos.
A9: 5 | B9: Diseño del modelo de datos y de clases: planes, suscripciones y usuarios + Documentación stakeholder's | C9: X | F9: Diseño del modelo de datos (entidades y relaciones) para planes de suscripcion, suscripciones activas y usuarios de la plataforma, diagrama de clases y documentación de stakeholder's
A10: 6 | B10: Elaboración de Documentación Formal / Plan de Proyecto | C10: X | F10: Redacción del documento formal del proyecto (Plan de Proyecto APT), que consolida contexto, objetivos, alcance, metodologia y planificación.
A11: 7 | B11: Hito: entrega Documentación Formal / Plan de Proyecto | C11: X | F11: Hito de control: entrega oficial de la Documentacion Formal y el Plan de Proyecto.
A12: 8 | B12: Elaboración Informe Fase 1 | C12: X | F12: Elaboración del Informe Fase 1, que documenta el avance conceptual y metodológico del proyecto.
A13: 9 | B13: Preparacion y ensayo presentacion Sumativa Fase 1 | C13: X | F13: Ensayo grupal de la presentación inicial, repartiendo tiempos y contenidos entre los integrantes.
A14: 10 | B14: Hito: presentacion Sumativa Fase 1 (heteroevaluacion, 20%) | C14: X | F14: Hito de evaluación: presentación inicial oral de 15 minutos
A15: 11 | B15: Diseño de la arquitectura (módulo pago y suscripción) | D15: X | F15: Diseño de la arquitectura de la solución: componentes de backend, frontend, base de datos y su interacción con la pasarela de pago externa.
A16: 12 | B16: Desarrollo CRUD de planes de suscripción (backend) | D16: X | F16: Desarrollo de las operaciones de backend (crear, leer, actualizar, eliminar) para la gestión de planes de suscripción.
A17: 13 | B17: Desarrollo de interfaz de gestión de planes (frontend) | D17: X | F17: Construcción de la interfaz que permite a un administrador crear, editar y visualizar los planes de suscripción disponibles.
A18: 14 | B18: Implementación de asignación de suscripción a usuario | D18: X | F18: Implementación de la lógica que asocia un plan de suscripción a un usuario específico de la plataforma.
A19: 15 | B19: Pruebas unitarias del modulo de planes | D19: X | F19: Ejecución de pruebas unitarias sobre las funciones del módulo de planes para verificar su correcto funcionamiento.
A20: 16 | B20: Hito: Incremento 2 validado | D20: X | F20: Hito de control: validación interna del Incremento 2 (gestion de planes y suscripciones) antes de avanzar al siguiente incremento.
A21: 17 | B21: Diseño UX/UI del flujo de checkout | D21: X | F21: Diseño de la experiencia e interfaz de usuario (UX/UI) del flujo de checkout, priorizando claridad y facilidad de uso.
A22: 18 | B22: Desarrollo del flujo de checkout (plan y datos de pago) | D22: X | F22: Desarrollo del flujo de checkout, incluyendo la selección del plan y el ingreso de los datos de pago.
A23: 19 | B23: Validación de formularios y reglas de negocio | D23: X | F23: Implementación de validaciones de formulario y reglas de negocio (campos obligatorios, formatos validos) en el flujo de compra.
A24: 20 | B24: Integración de checkout con módulo de suscripciones | D24: X | F24: Integración del flujo de checkout con el módulo de gestión de suscripciones desarrollado en el Incremento 2.
A25: 21 | B25: Mockups y prototipo navegable de checkout | D25: X | F25: Elaboración de mockups y un prototipo navegable del checkout para validar la experiencia de usuario antes de programarlo.
A26: 22 | B26: Pruebas end-to-end del flujo de checkout | D26: X | F26: Pruebas end-to-end del flujo completo de checkout, simulando el recorrido real de un usuario.
... A40: 36 | B40: Hito: Incremento 5 validado | D40: X | F40: Hito de control: validación del Incremento 5 Final validado.
A41: 37 | B41: Elaboracion del informe final | E41: X | F41: Elaboración del informe final del proyecto, consolidando el desarrollo de ingeniería realizado durante todo el semestre.
A42: 38 | B42: Redaccion de conclusiones y reflexiones individuales | E42: X | F42: Redacción de las conclusiones y reflexiones individuales de cada integrante del equipo.
A43: 39 | B43: Ensayo de presentacion final | E43: X | F43: Ensayo de la presentación grupal Final
A44: 40 | B44: Hito: entrega Informe Final | E44: X | F44: Hito de entrega: envio del Informe Final del proyecto en el formato y plazo establecidos.
A45: 41 | B45: Hito: presentación Final | E45: X | F45: Hito de evaluacion: presentación oral final del proyecto.
A46: 42 | B46: Actas de reunion y control de avance semanal | C46: X | D46: X | E46: X | F46: Elaboración semanal de actas de reunión y registro del estado de avance del proyecto durante todo el semestre.
A47: 43 | B47: Reuniones de seguimiento | C47: X | D47: X | E47: X | F47: Reuniones periodicas de seguimiento con el equipo, el docente guia y con la empresa para reportar avances, resolver dudas o conflictos.
A48: 44 | B48: Gestion de riesgos y control de cambios | C48: X | D48: X | E48: X | F48: Identificación, seguimiento y gestión de riesgos del proyecto, junto con el control de cambios de alcance o planificación.
